[ 2023-11-01 21:07:06,622 ] 96 werkzeug - INFO - [31m[1mWARNING: This is a development server. Do not use it in a production deployment. Use a production WSGI server instead.[0m
 * Running on all addresses (0.0.0.0)
 * Running on http://127.0.0.1:5000
 * Running on http://192.168.43.159:5000
[ 2023-11-01 21:07:06,622 ] 96 werkzeug - INFO - [33mPress CTRL+C to quit[0m
[ 2023-11-01 21:07:11,125 ] 96 werkzeug - INFO - 127.0.0.1 - - [01/Nov/2023 21:07:11] "GET / HTTP/1.1" 200 -
[ 2023-11-01 21:07:11,125 ] 96 werkzeug - INFO - 127.0.0.1 - - [01/Nov/2023 21:07:11] "[36mGET /static/style.css HTTP/1.1[0m" 304 -
[ 2023-11-01 21:07:13,110 ] 96 werkzeug - INFO - 127.0.0.1 - - [01/Nov/2023 21:07:13] "GET /predict_datapoint HTTP/1.1" 200 -
[ 2023-11-01 21:07:13,129 ] 96 werkzeug - INFO - 127.0.0.1 - - [01/Nov/2023 21:07:13] "[36mGET /static/style.css HTTP/1.1[0m" 304 -
[ 2023-11-01 21:07:23,622 ] 14 root - INFO - prediction for new data has started
[ 2023-11-01 21:07:23,892 ] 24 root - INFO - connection completed
[ 2023-11-01 21:07:23,892 ] 38 root - INFO - connection setup sucess
[ 2023-11-01 21:07:28,265 ] 40 root - INFO - inserting of data is completed
[ 2023-11-01 21:07:33,973 ] 54 root - INFO - there may be some error in mongo connection
[ 2023-11-01 21:07:33,973 ] 825 app - ERROR - Exception on /predict_datapoint [POST]
Traceback (most recent call last):
  File "E:\Working\Ineuron_intership\src\pipeline\data_storage.py", line 50, in Insertion
    new_csv.to_csv(self.new_file_location.new_data_csv,index=False)
  File "E:\Working\Ineuron_intership\venv\lib\site-packages\pandas\core\generic.py", line 3772, in to_csv
    return DataFrameRenderer(formatter).to_csv(
  File "E:\Working\Ineuron_intership\venv\lib\site-packages\pandas\io\formats\format.py", line 1186, in to_csv
    csv_formatter.save()
  File "E:\Working\Ineuron_intership\venv\lib\site-packages\pandas\io\formats\csvs.py", line 240, in save
    with get_handle(
  File "E:\Working\Ineuron_intership\venv\lib\site-packages\pandas\io\common.py", line 859, in get_handle
    handle = open(
PermissionError: [Errno 13] Permission denied: 'artifacts\\new_data_file.csv'

During handling of the above exception, another exception occurred:

Traceback (most recent call last):
  File "E:\Working\Ineuron_intership\venv\lib\site-packages\flask\app.py", line 1455, in wsgi_app
    response = self.full_dispatch_request()
  File "E:\Working\Ineuron_intership\venv\lib\site-packages\flask\app.py", line 869, in full_dispatch_request
    rv = self.handle_user_exception(e)
  File "E:\Working\Ineuron_intership\venv\lib\site-packages\flask\app.py", line 867, in full_dispatch_request
    rv = self.dispatch_request()
  File "E:\Working\Ineuron_intership\venv\lib\site-packages\flask\app.py", line 852, in dispatch_request
    return self.ensure_sync(self.view_functions[rule.endpoint])(**view_args)
  File "app.py", line 55, in predict_datapoint
    m.Insertion(new_data)
  File "E:\Working\Ineuron_intership\src\pipeline\data_storage.py", line 55, in Insertion
    raise CustomException(e,sys)
src.exception.CustomException: Error occured in python script name [E:\Working\Ineuron_intership\src\pipeline\data_storage.py] line number [50] error message [[Errno 13] Permission denied: 'artifacts\\new_data_file.csv']
[ 2023-11-01 21:07:34,048 ] 96 werkzeug - INFO - 127.0.0.1 - - [01/Nov/2023 21:07:34] "[35m[1mPOST /predict_datapoint HTTP/1.1[0m" 500 -
