[ 2023-11-01 21:06:00,835 ] 96 werkzeug - INFO - [31m[1mWARNING: This is a development server. Do not use it in a production deployment. Use a production WSGI server instead.[0m
 * Running on all addresses (0.0.0.0)
 * Running on http://127.0.0.1:5000
 * Running on http://192.168.43.159:5000
[ 2023-11-01 21:06:00,835 ] 96 werkzeug - INFO - [33mPress CTRL+C to quit[0m
[ 2023-11-01 21:06:04,116 ] 96 werkzeug - INFO - 127.0.0.1 - - [01/Nov/2023 21:06:04] "GET / HTTP/1.1" 200 -
[ 2023-11-01 21:06:04,117 ] 96 werkzeug - INFO - 127.0.0.1 - - [01/Nov/2023 21:06:04] "[36mGET /static/style.css HTTP/1.1[0m" 304 -
[ 2023-11-01 21:06:06,031 ] 96 werkzeug - INFO - 127.0.0.1 - - [01/Nov/2023 21:06:06] "GET /predict_datapoint HTTP/1.1" 200 -
[ 2023-11-01 21:06:06,052 ] 96 werkzeug - INFO - 127.0.0.1 - - [01/Nov/2023 21:06:06] "[36mGET /static/style.css HTTP/1.1[0m" 304 -
[ 2023-11-01 21:06:14,456 ] 14 root - INFO - prediction for new data has started
[ 2023-11-01 21:06:14,707 ] 24 root - INFO - connection completed
[ 2023-11-01 21:06:14,707 ] 38 root - INFO - connection setup sucess
[ 2023-11-01 21:06:23,408 ] 54 root - INFO - there may be some error in mongo connection
[ 2023-11-01 21:06:23,408 ] 825 app - ERROR - Exception on /predict_datapoint [POST]
Traceback (most recent call last):
  File "E:\Working\Ineuron_intership\src\pipeline\data_storage.py", line 39, in Insertion
    collection.insert_one(data)
  File "E:\Working\Ineuron_intership\venv\lib\site-packages\pymongo\collection.py", line 671, in insert_one
    self._insert_one(
  File "E:\Working\Ineuron_intership\venv\lib\site-packages\pymongo\collection.py", line 611, in _insert_one
    self.__database.client._retryable_write(acknowledged, _insert_command, session)
  File "E:\Working\Ineuron_intership\venv\lib\site-packages\pymongo\mongo_client.py", line 1568, in _retryable_write
    return self._retry_with_session(retryable, func, s, None)
  File "E:\Working\Ineuron_intership\venv\lib\site-packages\pymongo\mongo_client.py", line 1413, in _retry_with_session
    return self._retry_internal(retryable, func, session, bulk)
  File "E:\Working\Ineuron_intership\venv\lib\site-packages\pymongo\_csot.py", line 108, in csot_wrapper
    return func(self, *args, **kwargs)
  File "E:\Working\Ineuron_intership\venv\lib\site-packages\pymongo\mongo_client.py", line 1460, in _retry_internal
    return func(session, conn, retryable)
  File "E:\Working\Ineuron_intership\venv\lib\site-packages\pymongo\collection.py", line 599, in _insert_command
    result = conn.command(
  File "E:\Working\Ineuron_intership\venv\lib\site-packages\pymongo\helpers.py", line 315, in inner
    return func(*args, **kwargs)
  File "E:\Working\Ineuron_intership\venv\lib\site-packages\pymongo\pool.py", line 960, in command
    self._raise_connection_failure(error)
  File "E:\Working\Ineuron_intership\venv\lib\site-packages\pymongo\pool.py", line 932, in command
    return command(
  File "E:\Working\Ineuron_intership\venv\lib\site-packages\pymongo\network.py", line 150, in command
    request_id, msg, size, max_doc_size = message._op_msg(
  File "E:\Working\Ineuron_intership\venv\lib\site-packages\pymongo\message.py", line 765, in _op_msg
    return _op_msg_uncompressed(flags, command, identifier, docs, opts)
bson.errors.InvalidDocument: cannot encode object: array(['<=50K'], dtype=object), of type: <class 'numpy.ndarray'>

During handling of the above exception, another exception occurred:

Traceback (most recent call last):
  File "E:\Working\Ineuron_intership\venv\lib\site-packages\flask\app.py", line 1455, in wsgi_app
    response = self.full_dispatch_request()
  File "E:\Working\Ineuron_intership\venv\lib\site-packages\flask\app.py", line 869, in full_dispatch_request
    rv = self.handle_user_exception(e)
  File "E:\Working\Ineuron_intership\venv\lib\site-packages\flask\app.py", line 867, in full_dispatch_request
    rv = self.dispatch_request()
  File "E:\Working\Ineuron_intership\venv\lib\site-packages\flask\app.py", line 852, in dispatch_request
    return self.ensure_sync(self.view_functions[rule.endpoint])(**view_args)
  File "app.py", line 55, in predict_datapoint
    m.Insertion(new_data)
  File "E:\Working\Ineuron_intership\src\pipeline\data_storage.py", line 55, in Insertion
    raise CustomException(e,sys)
src.exception.CustomException: Error occured in python script name [E:\Working\Ineuron_intership\src\pipeline\data_storage.py] line number [39] error message [cannot encode object: array(['<=50K'], dtype=object), of type: <class 'numpy.ndarray'>]
[ 2023-11-01 21:06:23,426 ] 96 werkzeug - INFO - 127.0.0.1 - - [01/Nov/2023 21:06:23] "[35m[1mPOST /predict_datapoint HTTP/1.1[0m" 500 -
