[ 2023-11-01 20:57:40,737 ] 96 werkzeug - INFO - [31m[1mWARNING: This is a development server. Do not use it in a production deployment. Use a production WSGI server instead.[0m
 * Running on all addresses (0.0.0.0)
 * Running on http://127.0.0.1:5000
 * Running on http://127.0.0.1:5000
[ 2023-11-01 20:57:40,738 ] 96 werkzeug - INFO - [33mPress CTRL+C to quit[0m
[ 2023-11-01 20:58:01,607 ] 96 werkzeug - INFO - 127.0.0.1 - - [01/Nov/2023 20:58:01] "GET / HTTP/1.1" 200 -
[ 2023-11-01 20:58:01,622 ] 96 werkzeug - INFO - 127.0.0.1 - - [01/Nov/2023 20:58:01] "[36mGET /static/style.css HTTP/1.1[0m" 304 -
[ 2023-11-01 20:58:05,261 ] 96 werkzeug - INFO - 127.0.0.1 - - [01/Nov/2023 20:58:05] "GET /predict_datapoint HTTP/1.1" 200 -
[ 2023-11-01 20:58:05,279 ] 96 werkzeug - INFO - 127.0.0.1 - - [01/Nov/2023 20:58:05] "[36mGET /static/style.css HTTP/1.1[0m" 304 -
[ 2023-11-01 20:58:50,937 ] 31 root - INFO - there may be some error in mongo connection
[ 2023-11-01 20:58:50,937 ] 54 root - INFO - there may be some error in mongo connection
[ 2023-11-01 20:58:50,937 ] 825 app - ERROR - Exception on /predict_datapoint [POST]
Traceback (most recent call last):
  File "E:\Working\Ineuron_intership\venv\lib\site-packages\pymongo\srv_resolver.py", line 97, in _resolve_uri
    results = _resolve(
  File "E:\Working\Ineuron_intership\venv\lib\site-packages\pymongo\srv_resolver.py", line 45, in _resolve
    return resolver.resolve(*args, **kwargs)
  File "E:\Working\Ineuron_intership\venv\lib\site-packages\dns\resolver.py", line 1565, in resolve
    return get_default_resolver().resolve(
  File "E:\Working\Ineuron_intership\venv\lib\site-packages\dns\resolver.py", line 1318, in resolve
    (nameserver, tcp, backoff) = resolution.next_nameserver()
  File "E:\Working\Ineuron_intership\venv\lib\site-packages\dns\resolver.py", line 763, in next_nameserver
    raise NoNameservers(request=self.request, errors=self.errors)
dns.resolver.NoNameservers: All nameservers failed to answer the query _mongodb._tcp.cluster0.rkgp8jf.mongodb.net. IN SRV: Server Do53:192.168.43.251@53 answered [WinError 10065] A socket operation was attempted to an unreachable host

During handling of the above exception, another exception occurred:

Traceback (most recent call last):
  File "E:\Working\Ineuron_intership\src\pipeline\data_storage.py", line 23, in Mongo_connection
    client=MongoClient(url)
  File "E:\Working\Ineuron_intership\venv\lib\site-packages\pymongo\mongo_client.py", line 766, in __init__
    res = uri_parser.parse_uri(
  File "E:\Working\Ineuron_intership\venv\lib\site-packages\pymongo\uri_parser.py", line 556, in parse_uri
    nodes = dns_resolver.get_hosts()
  File "E:\Working\Ineuron_intership\venv\lib\site-packages\pymongo\srv_resolver.py", line 131, in get_hosts
    _, nodes = self._get_srv_response_and_hosts(True)
  File "E:\Working\Ineuron_intership\venv\lib\site-packages\pymongo\srv_resolver.py", line 111, in _get_srv_response_and_hosts
    results = self._resolve_uri(encapsulate_errors)
  File "E:\Working\Ineuron_intership\venv\lib\site-packages\pymongo\srv_resolver.py", line 105, in _resolve_uri
    raise ConfigurationError(str(exc))
pymongo.errors.ConfigurationError: All nameservers failed to answer the query _mongodb._tcp.cluster0.rkgp8jf.mongodb.net. IN SRV: Server Do53:192.168.43.251@53 answered [WinError 10065] A socket operation was attempted to an unreachable host

During handling of the above exception, another exception occurred:

Traceback (most recent call last):
  File "E:\Working\Ineuron_intership\src\pipeline\data_storage.py", line 37, in Insertion
    collection=self.Mongo_connection()
  File "E:\Working\Ineuron_intership\src\pipeline\data_storage.py", line 32, in Mongo_connection
    raise CustomException(e,sys)
src.exception.CustomException: Error occured in python script name [E:\Working\Ineuron_intership\src\pipeline\data_storage.py] line number [23] error message [All nameservers failed to answer the query _mongodb._tcp.cluster0.rkgp8jf.mongodb.net. IN SRV: Server Do53:192.168.43.251@53 answered [WinError 10065] A socket operation was attempted to an unreachable host]

During handling of the above exception, another exception occurred:

Traceback (most recent call last):
  File "E:\Working\Ineuron_intership\venv\lib\site-packages\flask\app.py", line 1455, in wsgi_app
    response = self.full_dispatch_request()
  File "E:\Working\Ineuron_intership\venv\lib\site-packages\flask\app.py", line 869, in full_dispatch_request
    rv = self.handle_user_exception(e)
  File "E:\Working\Ineuron_intership\venv\lib\site-packages\flask\app.py", line 867, in full_dispatch_request
    rv = self.dispatch_request()
  File "E:\Working\Ineuron_intership\venv\lib\site-packages\flask\app.py", line 852, in dispatch_request
    return self.ensure_sync(self.view_functions[rule.endpoint])(**view_args)
  File "app.py", line 45, in predict_datapoint
    m.Insertion(new_data)
  File "E:\Working\Ineuron_intership\src\pipeline\data_storage.py", line 55, in Insertion
    raise CustomException(e,sys)
src.exception.CustomException: Error occured in python script name [E:\Working\Ineuron_intership\src\pipeline\data_storage.py] line number [37] error message [Error occured in python script name [E:\Working\Ineuron_intership\src\pipeline\data_storage.py] line number [23] error message [All nameservers failed to answer the query _mongodb._tcp.cluster0.rkgp8jf.mongodb.net. IN SRV: Server Do53:192.168.43.251@53 answered [WinError 10065] A socket operation was attempted to an unreachable host]]
[ 2023-11-01 20:58:50,949 ] 96 werkzeug - INFO - 127.0.0.1 - - [01/Nov/2023 20:58:50] "[35m[1mPOST /predict_datapoint HTTP/1.1[0m" 500 -
