[ 2023-10-27 13:41:00,994 ] 96 werkzeug - INFO - [31m[1mWARNING: This is a development server. Do not use it in a production deployment. Use a production WSGI server instead.[0m
 * Running on all addresses (0.0.0.0)
 * Running on http://127.0.0.1:5000
 * Running on http://192.168.43.159:5000
[ 2023-10-27 13:41:00,994 ] 96 werkzeug - INFO - [33mPress CTRL+C to quit[0m
[ 2023-10-27 13:41:04,934 ] 96 werkzeug - INFO - 127.0.0.1 - - [27/Oct/2023 13:41:04] "GET / HTTP/1.1" 200 -
[ 2023-10-27 13:41:04,957 ] 96 werkzeug - INFO - 127.0.0.1 - - [27/Oct/2023 13:41:04] "[36mGET /static/style.css HTTP/1.1[0m" 304 -
[ 2023-10-27 13:41:07,419 ] 96 werkzeug - INFO - 127.0.0.1 - - [27/Oct/2023 13:41:07] "GET /predict_datapoint HTTP/1.1" 200 -
[ 2023-10-27 13:41:07,444 ] 96 werkzeug - INFO - 127.0.0.1 - - [27/Oct/2023 13:41:07] "[36mGET /static/style.css HTTP/1.1[0m" 304 -
[ 2023-10-27 13:41:26,317 ] 21 root - INFO - connection completed
[ 2023-10-27 13:41:26,317 ] 37 root - INFO - there may be some error in mongo connection
[ 2023-10-27 13:41:26,317 ] 78 root - INFO - there may be some problem in get as data frame
[ 2023-10-27 13:41:26,317 ] 825 app - ERROR - Exception on /predict_datapoint [POST]
Traceback (most recent call last):
  File "E:\Working\Ineuron_intership\src\pipeline\data_storage.py", line 35, in Insertion
    collection.insert_one(data)
  File "E:\Working\Ineuron_intership\venv\lib\site-packages\pymongo\collection.py", line 665, in insert_one
    common.validate_is_document_type("document", document)
  File "E:\Working\Ineuron_intership\venv\lib\site-packages\pymongo\common.py", line 555, in validate_is_document_type
    raise TypeError(
TypeError: document must be an instance of dict, bson.son.SON, bson.raw_bson.RawBSONDocument, or a type that inherits from collections.MutableMapping

During handling of the above exception, another exception occurred:

Traceback (most recent call last):
  File "E:\Working\Ineuron_intership\src\pipeline\prediction_pipeline.py", line 74, in get_as_dataframe
    self.storage.Insertion(df)
  File "E:\Working\Ineuron_intership\src\pipeline\data_storage.py", line 38, in Insertion
    raise CustomException(e,sys)
src.exception.CustomException: Error occured in python script name [E:\Working\Ineuron_intership\src\pipeline\data_storage.py] line number [35] error message [document must be an instance of dict, bson.son.SON, bson.raw_bson.RawBSONDocument, or a type that inherits from collections.MutableMapping]

During handling of the above exception, another exception occurred:

Traceback (most recent call last):
  File "E:\Working\Ineuron_intership\venv\lib\site-packages\flask\app.py", line 1455, in wsgi_app
    response = self.full_dispatch_request()
  File "E:\Working\Ineuron_intership\venv\lib\site-packages\flask\app.py", line 869, in full_dispatch_request
    rv = self.handle_user_exception(e)
  File "E:\Working\Ineuron_intership\venv\lib\site-packages\flask\app.py", line 867, in full_dispatch_request
    rv = self.dispatch_request()
  File "E:\Working\Ineuron_intership\venv\lib\site-packages\flask\app.py", line 852, in dispatch_request
    return self.ensure_sync(self.view_functions[rule.endpoint])(**view_args)
  File "app.py", line 30, in predict_datapoint
    final_new_data = data.get_as_dataframe()
  File "E:\Working\Ineuron_intership\src\pipeline\prediction_pipeline.py", line 79, in get_as_dataframe
    raise CustomData(e,sys)
TypeError: __init__() missing 8 required positional arguments: 'education_num', 'occupation', 'race', 'sex', 'capital_gain', 'capital_loss', 'hours_per_week', and 'country'
[ 2023-10-27 13:41:26,354 ] 96 werkzeug - INFO - 127.0.0.1 - - [27/Oct/2023 13:41:26] "[35m[1mPOST /predict_datapoint HTTP/1.1[0m" 500 -
